Workbook

Sheet 数据元
A1: 导入信息填写说明： 1、数据集名称、数据集英文名、数据元标准编码、数据元英文名、数据元名称，必填，其他字段请根据系统页面要求必填； 2、数据集排序、数据元排序为空则默认排到最后； 3、数据集名称，必填，支持中英文数字； 4、数据集英文名，必填，仅支持英文数字、特殊符号； 5、数据集排序，选填，仅支持数字； 6、数据元标准编码，必填，仅支持英文数字和小数点； 7、数据元英文，必填，仅支持英文数字、特殊符号； 8、数据元名称，必填，支持中英文数字； 9、数据元定义，选填，支持中英文数字、特殊符号； 10、数据元排序，选填，仅支持数字； 11、系统从第3行开始读取导入数据，请勿删除1、2行；
A2: 一级分类ID | B2: 数据集一级分类 | C2: 二级分类ID | D2: 数据集二级分类 | E2: 三级分类ID | F2: 数据集三级分类 | G2: 数据集英文名 | H2: 数据集排序 | I2: 数据元标准编码 | J2: 数据元英文名 | K2: 数据元驼峰名称 | L2: 数据元名称 | M2: 数据元定义 | N2: 数据元排序 | O2: 敏感性
A3: =VLOOKUP(F3,数据集标准分类!A:G,7,0) -> 01 | B3: =VLOOKUP(F3,数据集标准分类!A:F,6,0) -> 患者信息 | C3: =VLOOKUP(F3,数据集标准分类!A:E,5,0) -> 0101 | D3: =VLOOKUP(F3,数据集标准分类!A:D,4,0) -> 患者基本信息 | E3: =VLOOKUP(F3,数据集标准分类!A:C,3,0) -> 010101 | F3: 患者基本信息 | G3: =VLOOKUP(F3,数据集标准分类!A:B,2,0) -> patient_basic_information | H3: =VLOOKUP(F3,数据集标准分类!A:H,8,0) -> 1 | J3: health_archives_no | K3: healthArchivesNo | L3: 健康档案编号 | M3: 城乡居民个人健康档案的编号 | N3: 1
A4: =VLOOKUP(F4,数据集标准分类!A:G,7,0) -> 01 | B4: =VLOOKUP(F4,数据集标准分类!A:F,6,0) -> 患者信息 | C4: =VLOOKUP(F4,数据集标准分类!A:E,5,0) -> 0101 | D4: =VLOOKUP(F4,数据集标准分类!A:D,4,0) -> 患者基本信息 | E4: =VLOOKUP(F4,数据集标准分类!A:C,3,0) -> 010101 | F4: 患者基本信息 | G4: =VLOOKUP(F4,数据集标准分类!A:B,2,0) -> patient_basic_information | H4: =VLOOKUP(F4,数据集标准分类!A:H,8,0) -> 1 | I4: DE02.01.044.00 | J4: insur_class_code | K4: insurClassCode | L4: 医保类别代码 | M4: 患者本人参加的医疗保险类别在特定编码体系中的代码 | N4: 2
A5: =VLOOKUP(F5,数据集标准分类!A:G,7,0) -> 01 | B5: =VLOOKUP(F5,数据集标准分类!A:F,6,0) -> 患者信息 | C5: =VLOOKUP(F5,数据集标准分类!A:E,5,0) -> 0101 | D5: =VLOOKUP(F5,数据集标准分类!A:D,4,0) -> 患者基本信息 | E5: =VLOOKUP(F5,数据集标准分类!A:C,3,0) -> 010101 | F5: 患者基本信息 | G5: =VLOOKUP(F5,数据集标准分类!A:B,2,0) -> patient_basic_information | H5: =VLOOKUP(F5,数据集标准分类!A:H,8,0) -> 1 | I5: DE02.01.005.00 | J5: birth_date | K5: birthDate | L5: 出生日期 | M5: 患者出生当日的公元纪年日期的完整描述 | N5: 3
A6: =VLOOKUP(F6,数据集标准分类!A:G,7,0) -> 01 | B6: =VLOOKUP(F6,数据集标准分类!A:F,6,0) -> 患者信息 | C6: =VLOOKUP(F6,数据集标准分类!A:E,5,0) -> 0101 | D6: =VLOOKUP(F6,数据集标准分类!A:D,4,0) -> 患者基本信息 | E6: =VLOOKUP(F6,数据集标准分类!A:C,3,0) -> 010101 | F6: 患者基本信息 | G6: =VLOOKUP(F6,数据集标准分类!A:B,2,0) -> patient_basic_information | H6: =VLOOKUP(F6,数据集标准分类!A:H,8,0) -> 1 | I6: DE02.01.026.00 | J6: age | K6: age | L6: 年龄 | M6: 患者年龄满1周岁的实足年龄，为患者出生后按照日历计算的历法年龄，以实足年龄的相应整数填写 | N6: 4
A7: =VLOOKUP(F7,数据集标准分类!A:G,7,0) -> 01 | B7: =VLOOKUP(F7,数据集标准分类!A:F,6,0) -> 患者信息 | C7: =VLOOKUP(F7,数据集标准分类!A:E,5,0) -> 0101 | D7: =VLOOKUP(F7,数据集标准分类!A:D,4,0) -> 患者基本信息 | E7: =VLOOKUP(F7,数据集标准分类!A:C,3,0) -> 010101 | F7: 患者基本信息 | G7: =VLOOKUP(F7,数据集标准分类!A:B,2,0) -> patient_basic_information | H7: =VLOOKUP(F7,数据集标准分类!A:H,8,0) -> 1 | I7: DE02.01.032.00 | J7: chronological_age | K7: chronologicalAge | L7: 实足年龄 | M7: 年龄不足1周岁的实足年龄的月龄，以分数形式表示：分数的整数部分代表实足月龄，分数部分分母为30，分子为不足1个月的天数 | N7: 5
A8: =VLOOKUP(F8,数据集标准分类!A:G,7,0) -> 01 | B8: =VLOOKUP(F8,数据集标准分类!A:F,6,0) -> 患者信息 | C8: =VLOOKUP(F8,数据集标准分类!A:E,5,0) -> 0101 | D8: =VLOOKUP(F8,数据集标准分类!A:D,4,0) -> 患者基本信息 | E8: =VLOOKUP(F8,数据集标准分类!A:C,3,0) -> 010101 | F8: 患者基本信息 | G8: =VLOOKUP(F8,数据集标准分类!A:B,2,0) -> patient_basic_information | H8: =VLOOKUP(F8,数据集标准分类!A:H,8,0) -> 1 | I8: DE02.01.040.00 | J8: sex_code | K8: sexCode | L8: 性别代码 | M8: 患者生理性别在特定编码体系中的代码 | N8: 6
A9: =VLOOKUP(F9,数据集标准分类!A:G,7,0) -> 01 | B9: =VLOOKUP(F9,数据集标准分类!A:F,6,0) -> 患者信息 | C9: =VLOOKUP(F9,数据集标准分类!A:E,5,0) -> 0101 | D9: =VLOOKUP(F9,数据集标准分类!A:D,4,0) -> 患者基本信息 | E9: =VLOOKUP(F9,数据集标准分类!A:C,3,0) -> 010101 | F9: 患者基本信息 | G9: =VLOOKUP(F9,数据集标准分类!A:B,2,0) -> patient_basic_information | H9: =VLOOKUP(F9,数据集标准分类!A:H,8,0) -> 1 | I9: DE01.00.004.00 | J9: case_no | K9: caseNo | L9: 病案号 | M9: 本医疗机构为患者住院病案设置的唯一性编码。原则上，同一患者在同一医疗机构多次住院应当使用同一病案号 | N9: 7
A10: =VLOOKUP(F10,数据集标准分类!A:G,7,0) -> 01 | B10: =VLOOKUP(F10,数据集标准分类!A:F,6,0) -> 患者信息 | C10: =VLOOKUP(F10,数据集标准分类!A:E,5,0) -> 0101 | D10: =VLOOKUP(F10,数据集标准分类!A:D,4,0) -> 患者基本信息 | E10: =VLOOKUP(F10,数据集标准分类!A:C,3,0) -> 010101 | F10: 患者基本信息 | G10: =VLOOKUP(F10,数据集标准分类!A:B,2,0) -> patient_basic_information | H10: =VLOOKUP(F10,数据集标准分类!A:H,8,0) -> 1 | I10: DE02.01.018.00 | J10: marital_status_code | K10: maritalStatusCode | L10: 婚姻状况代码 | M10: 患者当前婚姻状况在特定编码体系中的代码 | N10: 8
A11: =VLOOKUP(F11,数据集标准分类!A:G,7,0) -> 01 | B11: =VLOOKUP(F11,数据集标准分类!A:F,6,0) -> 患者信息 | C11: =VLOOKUP(F11,数据集标准分类!A:E,5,0) -> 0101 | D11: =VLOOKUP(F11,数据集标准分类!A:D,4,0) -> 患者基本信息 | E11: =VLOOKUP(F11,数据集标准分类!A:C,3,0) -> 010101 | F11: 患者基本信息 | G11: =VLOOKUP(F11,数据集标准分类!A:B,2,0) -> patient_basic_information | H11: =VLOOKUP(F11,数据集标准分类!A:H,8,0) -> 1 | I11: DE02.01.052.00 | J11: occup_class_code | K11: occupClassCode | L11: 职业分类代码 | M11: 患者当前从事的职业类别在特定编码体系中的代码 | N11: 9
A12: =VLOOKUP(F12,数据集标准分类!A:G,7,0) -> 01 | B12: =VLOOKUP(F12,数据集标准分类!A:F,6,0) -> 患者信息 | C12: =VLOOKUP(F12,数据集标准分类!A:E,5,0) -> 0101 | D12: =VLOOKUP(F12,数据集标准分类!A:D,4,0) -> 患者基本信息 | E12: =VLOOKUP(F12,数据集标准分类!A:C,3,0) -> 010101 | F12: 患者基本信息 | G12: =VLOOKUP(F12,数据集标准分类!A:B,2,0) -> patient_basic_information | H12: =VLOOKUP(F12,数据集标准分类!A:H,8,0) -> 1 | I12: DE02.01.039.68 | J12: contacts_name | K12: contactsName | L12: 联系人姓名 | M12: 联系人在公安户籍管理部门正式登记注册的姓氏和名称 | N12: 10
A13: =VLOOKUP(F13,数据集标准分类!A:G,7,0) -> 01 | B13: =VLOOKUP(F13,数据集标准分类!A:F,6,0) -> 患者信息 | C13: =VLOOKUP(F13,数据集标准分类!A:E,5,0) -> 0101 | D13: =VLOOKUP(F13,数据集标准分类!A:D,4,0) -> 患者基本信息 | E13: =VLOOKUP(F13,数据集标准分类!A:C,3,0) -> 010101 | F13: 患者基本信息 | G13: =VLOOKUP(F13,数据集标准分类!A:B,2,0) -> patient_basic_information | H13: =VLOOKUP(F13,数据集标准分类!A:H,8,0) -> 1 | I13: DE06.00.050.00 | J13: create_archives_date | K13: createArchivesDate | L13: 建档日期 | M13: 患者电子病历初次建档完成时的公元纪年日期和时间的完整描述 | N13: 11
A14: =VLOOKUP(F14,数据集标准分类!A:G,7,0) -> 01 | B14: =VLOOKUP(F14,数据集标准分类!A:F,6,0) -> 患者信息 | C14: =VLOOKUP(F14,数据集标准分类!A:E,5,0) -> 0101 | D14: =VLOOKUP(F14,数据集标准分类!A:D,4,0) -> 患者基本信息 | E14: =VLOOKUP(F14,数据集标准分类!A:C,3,0) -> 010101 | F14: 患者基本信息 | G14: =VLOOKUP(F14,数据集标准分类!A:B,2,0) -> patient_basic_information | H14: =VLOOKUP(F14,数据集标准分类!A:H,8,0) -> 1 | I14: DE02.01.039.01 | J14: patient_name | K14: patientName | L14: 患者姓名 | M14: 首次为患者建立电子病历的人员在公安户籍管理部门正式登记注册的姓氏和名称 | N14: 12
A15: =VLOOKUP(F15,数据集标准分类!A:G,7,0) -> 01 | B15: =VLOOKUP(F15,数据集标准分类!A:F,6,0) -> 患者信息 | C15: =VLOOKUP(F15,数据集标准分类!A:E,5,0) -> 0101 | D15: =VLOOKUP(F15,数据集标准分类!A:D,4,0) -> 患者基本信息 | E15: =VLOOKUP(F15,数据集标准分类!A:C,3,0) -> 010102 | F15: 基本健康信息 | G15: =VLOOKUP(F15,数据集标准分类!A:B,2,0) -> basic_health_information | H15: =VLOOKUP(F15,数据集标准分类!A:H,8,0) -> 2 | I15: DE04.50.001.00 | J15: abo_blood_group_code | K15: aboBloodGroupCode | L15: ABO血型代码 | M15: 进行血型检查明确，或既往病历资料能够明确的患者ABO血型类别在特定编码体系中的代码 | N15: 1
... A38: =VLOOKUP(F38,数据集标准分类!A:G,7,0) -> 01 | B38: =VLOOKUP(F38,数据集标准分类!A:F,6,0) -> 患者信息 | C38: =VLOOKUP(F38,数据集标准分类!A:E,5,0) -> 0101 | D38: =VLOOKUP(F38,数据集标准分类!A:D,4,0) -> 患者基本信息 | E38: =VLOOKUP(F38,数据集标准分类!A:C,3,0) -> 010103 | F38: 卫生事件摘要 | G38: =VLOOKUP(F38,数据集标准分类!A:B,2,0) -> health_event_abstract | H38: =VLOOKUP(F38,数据集标准分类!A:H,8,0) -> 3 | I38: DE06.00.093.00 | J38: op_oper_code | K38: opOperCode | L38: 手术/操作代码 | M38: 患者住院期间实施的手术及操作在特定编码体系中的编码(按照《T/CHIA001-2017 手术、操作分类与代码》团体标准的分类代 | N38: 13
A39: =VLOOKUP(F39,数据集标准分类!A:G,7,0) -> 01 | B39: =VLOOKUP(F39,数据集标准分类!A:F,6,0) -> 患者信息 | C39: =VLOOKUP(F39,数据集标准分类!A:E,5,0) -> 0101 | D39: =VLOOKUP(F39,数据集标准分类!A:D,4,0) -> 患者基本信息 | E39: =VLOOKUP(F39,数据集标准分类!A:C,3,0) -> 010103 | F39: 卫生事件摘要 | G39: =VLOOKUP(F39,数据集标准分类!A:B,2,0) -> health_event_abstract | H39: =VLOOKUP(F39,数据集标准分类!A:H,8,0) -> 3 | I39: DE08.50.022.00 | J39: drug_name | L39: 药品名称 | M39: 与本次就诊相关的关键药物通用名称 | N39: 14
A40: =VLOOKUP(F40,数据集标准分类!A:G,7,0) -> 01 | B40: =VLOOKUP(F40,数据集标准分类!A:F,6,0) -> 患者信息 | C40: =VLOOKUP(F40,数据集标准分类!A:E,5,0) -> 0101 | D40: =VLOOKUP(F40,数据集标准分类!A:D,4,0) -> 患者基本信息 | E40: =VLOOKUP(F40,数据集标准分类!A:C,3,0) -> 010103 | F40: 卫生事件摘要 | G40: =VLOOKUP(F40,数据集标准分类!A:B,2,0) -> health_event_abstract | H40: =VLOOKUP(F40,数据集标准分类!A:H,8,0) -> 3 | I40: DE06.00.136.00 | J40: drug_usage | K40: drugUsage | L40: 药品用法 | M40: 与本次就诊相关的关键药物（含中药）治疗疾病具体用法的描述 | N40: 15
A41: =VLOOKUP(F41,数据集标准分类!A:G,7,0) -> 01 | B41: =VLOOKUP(F41,数据集标准分类!A:F,6,0) -> 患者信息 | C41: =VLOOKUP(F41,数据集标准分类!A:E,5,0) -> 0101 | D41: =VLOOKUP(F41,数据集标准分类!A:D,4,0) -> 患者基本信息 | E41: =VLOOKUP(F41,数据集标准分类!A:C,3,0) -> 010103 | F41: 卫生事件摘要 | G41: =VLOOKUP(F41,数据集标准分类!A:B,2,0) -> health_event_abstract | H41: =VLOOKUP(F41,数据集标准分类!A:H,8,0) -> 3 | I41: DE06.00.129.00 | J41: drug_adr_flag | K41: drugAdrFlag | L41: 药品不良反应标志 | M41: 对可能影响患者诊治的、严重的药物不良反应描述，包括：药物不良反应的表现、相关处理及结局 | N41: 16
A42: =VLOOKUP(F42,数据集标准分类!A:G,7,0) -> 01 | B42: =VLOOKUP(F42,数据集标准分类!A:F,6,0) -> 患者信息 | C42: =VLOOKUP(F42,数据集标准分类!A:E,5,0) -> 0101 | D42: =VLOOKUP(F42,数据集标准分类!A:D,4,0) -> 患者基本信息 | E42: =VLOOKUP(F42,数据集标准分类!A:C,3,0) -> 010103 | F42: 卫生事件摘要 | G42: =VLOOKUP(F42,数据集标准分类!A:B,2,0) -> health_event_abstract | H42: =VLOOKUP(F42,数据集标准分类!A:H,8,0) -> 3 | I42: DE06.00.164.00 | J42: chm_use_class_code | K42: chmUseClassCode | L42: 中药使用类别代码 | M42: 临床治疗中中药使用情况分类在特定编码体系中的代码 | N42: 17
A43: =VLOOKUP(F43,数据集标准分类!A:G,7,0) -> 01 | B43: =VLOOKUP(F43,数据集标准分类!A:F,6,0) -> 患者信息 | C43: =VLOOKUP(F43,数据集标准分类!A:E,5,0) -> 0101 | D43: =VLOOKUP(F43,数据集标准分类!A:D,4,0) -> 患者基本信息 | E43: =VLOOKUP(F43,数据集标准分类!A:C,3,0) -> 010103 | F43: 卫生事件摘要 | G43: =VLOOKUP(F43,数据集标准分类!A:B,2,0) -> health_event_abstract | H43: =VLOOKUP(F43,数据集标准分类!A:H,8,0) -> 3 | I43: DE06.00.251.00 | J43: op_oper_method | K43: opOperMethod | L43: 手术/操作方法 | M43: 临床医师对患者实施的除检查/检验、用药、手术/操作以外的医学处置的描述(手术/操作方法的详细描述) | N43: 18
A44: =VLOOKUP(F44,数据集标准分类!A:G,7,0) -> 01 | B44: =VLOOKUP(F44,数据集标准分类!A:F,6,0) -> 患者信息 | C44: =VLOOKUP(F44,数据集标准分类!A:E,5,0) -> 0101 | D44: =VLOOKUP(F44,数据集标准分类!A:D,4,0) -> 患者基本信息 | E44: =VLOOKUP(F44,数据集标准分类!A:C,3,0) -> 010103 | F44: 卫生事件摘要 | G44: =VLOOKUP(F44,数据集标准分类!A:B,2,0) -> health_event_abstract | H44: =VLOOKUP(F44,数据集标准分类!A:H,8,0) -> 3 | I44: DE05.01.021.00 | J44: child_underlying_cod_diag_code | K44: childUnderlyingCodDiagCode | L44: 儿童根本死因ICD-10代码 | M44: 导致患者死亡的最根本疾病的诊断代码 | N44: 19
A45: =VLOOKUP(F45,数据集标准分类!A:G,7,0) -> 01 | B45: =VLOOKUP(F45,数据集标准分类!A:F,6,0) -> 患者信息 | C45: =VLOOKUP(F45,数据集标准分类!A:E,5,0) -> 0101 | D45: =VLOOKUP(F45,数据集标准分类!A:D,4,0) -> 患者基本信息 | E45: 010103 | F45: 卫生事件摘要 | G45: =VLOOKUP(F45,数据集标准分类!A:B,2,0) -> health_event_abstract | H45: =VLOOKUP(F45,数据集标准分类!A:H,8,0) -> 3 | I45: DE05.10.113.00 | J45: treat_result_code | K45: treatResultCode | L45: 治疗结果代码 | M45: 出院时患者所患的每种疾病的治疗结果类别在特定编码体系中的代码 | N45: 20
A46: =VLOOKUP(F46,数据集标准分类!A:G,7,0) -> 01 | B46: =VLOOKUP(F46,数据集标准分类!A:F,6,0) -> 患者信息 | C46: =VLOOKUP(F46,数据集标准分类!A:E,5,0) -> 0101 | D46: =VLOOKUP(F46,数据集标准分类!A:D,4,0) -> 患者基本信息 | E46: 010103 | F46: 卫生事件摘要 | G46: =VLOOKUP(F46,数据集标准分类!A:B,2,0) -> health_event_abstract | H46: =VLOOKUP(F46,数据集标准分类!A:H,8,0) -> 3 | I46: DE02.01.039.25 | J46: resp_physician_name | K46: respPhysicianName | L46: 责任医师姓名 | M46: 负责患者诊疗的主治医师以上的医师在公安户籍管理部门正式登记注册的姓氏和名称 | N46: 21
A47: =VLOOKUP(F47,数据集标准分类!A:G,7,0) -> 02 | B47: =VLOOKUP(F47,数据集标准分类!A:F,6,0) -> 电子病历 | C47: =VLOOKUP(F47,数据集标准分类!A:E,5,0) -> 0201 | D47: =VLOOKUP(F47,数据集标准分类!A:D,4,0) -> 病案首页 | E47: 020101 | F47: 住院病案首页 | G47: inpatient_case_homepage | H47: =VLOOKUP(F47,数据集标准分类!A:H,8,0) -> 4 | I47: DE02.01.030.02 | J47: patient_id_cred_no | K47: patientIdCredNo | L47: 患者身份证件号码 | M47: 患者的身份证件上的唯一法定标识符 | N47: 1
A48: =VLOOKUP(F48,数据集标准分类!A:G,7,0) -> 02 | B48: =VLOOKUP(F48,数据集标准分类!A:F,6,0) -> 电子病历 | C48: =VLOOKUP(F48,数据集标准分类!A:E,5,0) -> 0201 | D48: =VLOOKUP(F48,数据集标准分类!A:D,4,0) -> 病案首页 | E48: =VLOOKUP(F48,数据集标准分类!A:C,3,0) -> 020101 | F48: 住院病案首页 | G48: inpatient_case_homepage | H48: =VLOOKUP(F48,数据集标准分类!A:H,8,0) -> 4 | I48: DE02.01.039.00 | J48: full_name | K48: fullName | L48: 姓名 | M48: 为患者实施手术的主要执行人员在公安户籍管理部门正式登记注册的姓氏和名称 | N48: 2
A49: =VLOOKUP(F49,数据集标准分类!A:G,7,0) -> 02 | B49: =VLOOKUP(F49,数据集标准分类!A:F,6,0) -> 电子病历 | C49: =VLOOKUP(F49,数据集标准分类!A:E,5,0) -> 0201 | D49: =VLOOKUP(F49,数据集标准分类!A:D,4,0) -> 病案首页 | E49: =VLOOKUP(F49,数据集标准分类!A:C,3,0) -> 020101 | F49: 住院病案首页 | G49: =VLOOKUP(F49,数据集标准分类!A:B,2,0) -> inpatient_case_homepage | H49: =VLOOKUP(F49,数据集标准分类!A:H,8,0) -> 4 | I49: ZOE99.01.00.176 | J49: sex_name | K49: sexName | L49: 性别 | N49: 3
A50: =VLOOKUP(F50,数据集标准分类!A:G,7,0) -> 02 | B50: =VLOOKUP(F50,数据集标准分类!A:F,6,0) -> 电子病历 | C50: =VLOOKUP(F50,数据集标准分类!A:E,5,0) -> 0201 | D50: =VLOOKUP(F50,数据集标准分类!A:D,4,0) -> 病案首页 | E50: =VLOOKUP(F50,数据集标准分类!A:C,3,0) -> 020101 | F50: 住院病案首页 | G50: =VLOOKUP(F50,数据集标准分类!A:B,2,0) -> inpatient_case_homepage | H50: =VLOOKUP(F50,数据集标准分类!A:H,8,0) -> 4 | I50: DE02.01.005.00 | J50: birth_date | K50: birthDate | L50: 出生日期 | N50: 4
A51: =VLOOKUP(F51,数据集标准分类!A:G,7,0) -> 02 | B51: =VLOOKUP(F51,数据集标准分类!A:F,6,0) -> 电子病历 | C51: =VLOOKUP(F51,数据集标准分类!A:E,5,0) -> 0201 | D51: =VLOOKUP(F51,数据集标准分类!A:D,4,0) -> 病案首页 | E51: =VLOOKUP(F51,数据集标准分类!A:C,3,0) -> 020101 | F51: 住院病案首页 | G51: =VLOOKUP(F51,数据集标准分类!A:B,2,0) -> inpatient_case_homepage | H51: =VLOOKUP(F51,数据集标准分类!A:H,8,0) -> 4 | I51: DE02.01.015.00 | J51: nationality | K51: nationality | L51: 国籍 | N51: 5
A52: =VLOOKUP(F52,数据集标准分类!A:G,7,0) -> 02 | B52: =VLOOKUP(F52,数据集标准分类!A:F,6,0) -> 电子病历 | C52: =VLOOKUP(F52,数据集标准分类!A:E,5,0) -> 0201 | D52: =VLOOKUP(F52,数据集标准分类!A:D,4,0) -> 病案首页 | E52: =VLOOKUP(F52,数据集标准分类!A:C,3,0) -> 020101 | F52: 住院病案首页 | G52: =VLOOKUP(F52,数据集标准分类!A:B,2,0) -> inpatient_case_homepage | H52: =VLOOKUP(F52,数据集标准分类!A:H,8,0) -> 4 | I52: DE02.01.025.00 | J52: nation_code | K52: nationCode | L52: 民族 | N52: 6
A53: =VLOOKUP(F53,数据集标准分类!A:G,7,0) -> 02 | B53: =VLOOKUP(F53,数据集标准分类!A:F,6,0) -> 电子病历 | C53: =VLOOKUP(F53,数据集标准分类!A:E,5,0) -> 0201 | D53: =VLOOKUP(F53,数据集标准分类!A:D,4,0) -> 病案首页 | E53: =VLOOKUP(F53,数据集标准分类!A:C,3,0) -> 020101 | F53: 住院病案首页 | G53: =VLOOKUP(F53,数据集标准分类!A:B,2,0) -> inpatient_case_homepage | H53: =VLOOKUP(F53,数据集标准分类!A:H,8,0) -> 4 | I53: ZOE99.00.03.6906 | J53: native | K53: native | L53: 籍贯 | N53: 7
A54: =VLOOKUP(F54,数据集标准分类!A:G,7,0) -> 02 | B54: =VLOOKUP(F54,数据集标准分类!A:F,6,0) -> 电子病历 | C54: =VLOOKUP(F54,数据集标准分类!A:E,5,0) -> 0201 | D54: =VLOOKUP(F54,数据集标准分类!A:D,4,0) -> 病案首页 | E54: =VLOOKUP(F54,数据集标准分类!A:C,3,0) -> 020101 | F54: 住院病案首页 | G54: =VLOOKUP(F54,数据集标准分类!A:B,2,0) -> inpatient_case_homepage | H54: =VLOOKUP(F54,数据集标准分类!A:H,8,0) -> 4 | I54: ZOE99.00.03.7098 | J54: occup_name | K54: occupName | L54: 职业 | N54: 8
A55: =VLOOKUP(F55,数据集标准分类!A:G,7,0) -> 02 | B55: =VLOOKUP(F55,数据集标准分类!A:F,6,0) -> 电子病历 | C55: =VLOOKUP(F55,数据集标准分类!A:E,5,0) -> 0201 | D55: =VLOOKUP(F55,数据集标准分类!A:D,4,0) -> 病案首页 | E55: =VLOOKUP(F55,数据集标准分类!A:C,3,0) -> 020101 | F55: 住院病案首页 | G55: =VLOOKUP(F55,数据集标准分类!A:B,2,0) -> inpatient_case_homepage | H55: =VLOOKUP(F55,数据集标准分类!A:H,8,0) -> 4 | I55: ZOE99.00.03.4044 | J55: marital | K55: marital | L55: 婚姻 | N55: 9
A56: =VLOOKUP(F56,数据集标准分类!A:G,7,0) -> 02 | B56: =VLOOKUP(F56,数据集标准分类!A:F,6,0) -> 电子病历 | C56: =VLOOKUP(F56,数据集标准分类!A:E,5,0) -> 0201 | D56: =VLOOKUP(F56,数据集标准分类!A:D,4,0) -> 病案首页 | E56: =VLOOKUP(F56,数据集标准分类!A:C,3,0) -> 020101 | F56: 住院病案首页 | G56: =VLOOKUP(F56,数据集标准分类!A:B,2,0) -> inpatient_case_homepage | H56: =VLOOKUP(F56,数据集标准分类!A:H,8,0) -> 4 | I56: ZOE99.00.03.3036 | J56: birthplace | K56: birthplace | L56: 出生地 | N56: 10
A57: =VLOOKUP(F57,数据集标准分类!A:G,7,0) -> 02 | B57: =VLOOKUP(F57,数据集标准分类!A:F,6,0) -> 电子病历 | C57: =VLOOKUP(F57,数据集标准分类!A:E,5,0) -> 0201 | D57: =VLOOKUP(F57,数据集标准分类!A:D,4,0) -> 病案首页 | E57: =VLOOKUP(F57,数据集标准分类!A:C,3,0) -> 020101 | F57: 住院病案首页 | G57: =VLOOKUP(F57,数据集标准分类!A:B,2,0) -> inpatient_case_homepage | H57: =VLOOKUP(F57,数据集标准分类!A:H,8,0) -> 4 | I57: ZOE99.00.00.172 | J57: current_resid_addr_code | K57: currentResidAddrCode | L57: 现住址 | N57: 11
A58: =VLOOKUP(F58,数据集标准分类!A:G,7,0) -> 02 | B58: =VLOOKUP(F58,数据集标准分类!A:F,6,0) -> 电子病历 | C58: =VLOOKUP(F58,数据集标准分类!A:E,5,0) -> 0201 | D58: =VLOOKUP(F58,数据集标准分类!A:D,4,0) -> 病案首页 | E58: =VLOOKUP(F58,数据集标准分类!A:C,3,0) -> 020101 | F58: 住院病案首页 | G58: =VLOOKUP(F58,数据集标准分类!A:B,2,0) -> inpatient_case_homepage | H58: =VLOOKUP(F58,数据集标准分类!A:H,8,0) -> 4 | I58: DE08.10.007.00 | J58: work_unit_name | K58: workUnitName | L58: 工作单位 | N58: 12
A59: =VLOOKUP(F59,数据集标准分类!A:G,7,0) -> 02 | B59: =VLOOKUP(F59,数据集标准分类!A:F,6,0) -> 电子病历 | C59: =VLOOKUP(F59,数据集标准分类!A:E,5,0) -> 0201 | D59: =VLOOKUP(F59,数据集标准分类!A:D,4,0) -> 病案首页 | E59: =VLOOKUP(F59,数据集标准分类!A:C,3,0) -> 020101 | F59: 住院病案首页 | G59: =VLOOKUP(F59,数据集标准分类!A:B,2,0) -> inpatient_case_homepage | H59: =VLOOKUP(F59,数据集标准分类!A:H,8,0) -> 4 | I59: ZOE99.00.03.3456 | J59: unit_addr | K59: unitAddr | L59: 单位地址 | N59: 13
A60: =VLOOKUP(F60,数据集标准分类!A:G,7,0) -> 02 | B60: =VLOOKUP(F60,数据集标准分类!A:F,6,0) -> 电子病历 | C60: =VLOOKUP(F60,数据集标准分类!A:E,5,0) -> 0201 | D60: =VLOOKUP(F60,数据集标准分类!A:D,4,0) -> 病案首页 | E60: =VLOOKUP(F60,数据集标准分类!A:C,3,0) -> 020101 | F60: 住院病案首页 | G60: =VLOOKUP(F60,数据集标准分类!A:B,2,0) -> inpatient_case_homepage | H60: =VLOOKUP(F60,数据集标准分类!A:H,8,0) -> 4 | I60: DE02.01.010.04 | J60: work_unit_phone_no | K60: workUnitPhoneNo | L60: 单位电话 | N60: 14
... A66: =VLOOKUP(F66,数据集标准分类!A:G,7,0) -> 02 | B66: =VLOOKUP(F66,数据集标准分类!A:F,6,0) -> 电子病历 | C66: =VLOOKUP(F66,数据集标准分类!A:E,5,0) -> 0201 | D66: =VLOOKUP(F66,数据集标准分类!A:D,4,0) -> 病案首页 | E66: =VLOOKUP(F66,数据集标准分类!A:C,3,0) -> 020101 | F66: 住院病案首页 | G66: =VLOOKUP(F66,数据集标准分类!A:B,2,0) -> inpatient_case_homepage | H66: =VLOOKUP(F66,数据集标准分类!A:H,8,0) -> 4 | I66: ZOE99.00.03.7675 | J66: allergy_drug | K66: allergyDrug | L66: 过敏药物名 | N66: 20
A67: =VLOOKUP(F67,数据集标准分类!A:G,7,0) -> 02 | B67: =VLOOKUP(F67,数据集标准分类!A:F,6,0) -> 电子病历 | C67: =VLOOKUP(F67,数据集标准分类!A:E,5,0) -> 0201 | D67: =VLOOKUP(F67,数据集标准分类!A:D,4,0) -> 病案首页 | E67: =VLOOKUP(F67,数据集标准分类!A:C,3,0) -> 020101 | F67: 住院病案首页 | G67: =VLOOKUP(F67,数据集标准分类!A:B,2,0) -> inpatient_case_homepage | H67: =VLOOKUP(F67,数据集标准分类!A:H,8,0) -> 4 | I67: DE04.50.001.00 | J67: abo_blood_group_code | K67: aboBloodGroupCode | L67: ABO血型代码 | M67: 在本次住院期间进行血型检查明确，或既往病历资料能够明确的患者ABO血型类别在特定编码体系中的代码 | N67: 21
...

Sheet 数据集标准分类
A1: 三级目录名称 | B1: 三级目录英文名称 | C1: 三级目录代码 | D1: 二级目录名称 | E1: 二级目录代码 | F1: 一级目录名称 | G1: 一级目录代码 | H1: 数据集排序 | I1: 新增时间 | J1: 新增人 | K1: 备注
A2: 患者基本信息 | B2: patient_basic_information | C2: 010101 | D2: 患者基本信息 | E2: 0101 | F2: 患者信息 | G2: 01 | H2: =ROW(A2)-1 -> 1
A3: 基本健康信息 | B3: basic_health_information | C3: 010102 | D3: 患者基本信息 | E3: 0101 | F3: 患者信息 | G3: 01 | H3: =ROW(A3)-1 -> 2
A4: 卫生事件摘要 | B4: health_event_abstract | C4: 010103 | D4: 患者基本信息 | E4: 0101 | F4: 患者信息 | G4: 01 | H4: =ROW(A4)-1 -> 3
A5: 住院病案首页 | B5: inpatient_case_homepage | C5: 020101 | D5: 病案首页 | E5: 0201 | F5: 电子病历 | G5: 02 | H5: =ROW(A5)-1 -> 4
A6: 中医住院病案首页 | B6: tcm_inp_case_homepage | C6: 020102 | D6: 病案首页 | E6: 0201 | F6: 电子病历 | G6: 02 | H6: =ROW(A6)-1 -> 5
A7: 门(急)诊病案首页 | B7: outp_emer_case_homepage | C7: 020103 | D7: 病案首页 | E7: 0201 | F7: 电子病历 | G7: 02 | H7: =ROW(A7)-1 -> 6
A8: 入院记录 | B8: admission_record | C8: 020201 | D8: 入院记录 | E8: 0202 | F8: 电子病历 | G8: 02 | H8: =ROW(A8)-1 -> 7
A9: 24h内入出院记录 | B9: admsn_dc_record_24_h | C9: 020202 | D9: 入院记录 | E9: 0202 | F9: 电子病历 | G9: 02 | H9: =ROW(A9)-1 -> 8
A10: 24h内入院死亡记录 | B10: admsn_death_record | C10: 020203 | D10: 入院记录 | E10: 0202 | F10: 电子病历 | G10: 02 | H10: =ROW(A10)-1 -> 9
A11: 首次病程记录 | B11: first_course_record | C11: 020301 | D11: 病程记录 | E11: 0203 | F11: 电子病历 | G11: 02 | H11: =ROW(A11)-1 -> 10
A12: 日常病程记录 | B12: daily_course_record | C12: 020302 | D12: 病程记录 | E12: 0203 | F12: 电子病历 | G12: 02 | H12: =ROW(A12)-1 -> 11
A13: 上级医师查房记录 | B13: parent_phy_ward_rounds_rec | C13: 020303 | D13: 病程记录 | E13: 0203 | F13: 电子病历 | G13: 02 | H13: =ROW(A13)-1 -> 12
... A125: 检查记录 | B125: examination_record | C125: 070501 | D125: 检查记录 | E125: 0705 | F125: 第三方系统 | G125: 07 | H125: =ROW(A125)-1 -> 124

Sheet 电子病历分类
A1: mr_std_cont_name | B1: mr_std_cont_code | C1: mr_std_cont_name | D1: parent_mr_std_cont_code | E1: spell_code | F1: wbzx_code | G1: sort_no | H1: create_time | I1: creator_code | J1: modify_time | K1: modifier_code | L1: data_state
A2: 病案首页 | B2: 1 | C2: 病案首页 | D2: 000 | E2: BASY | F2: UPUD | G2: 0 | L2: 1
A3: 入院记录 | B3: 2 | C3: 入院记录 | D3: 000 | E3: RYJL | F3: TBYV | G3: 2 | L3: 1
A4: 病程记录 | B4: 3 | C4: 病程记录 | D4: 000 | E4: BCJL | F4: UTYV | G4: 3 | L4: 1
A5: 会诊记录 | B5: 4 | C5: 会诊记录 | D5: 000 | E5: HZJL | F5: WYYV | G5: 4 | L5: 1
A6: 出院记录 | B6: 5 | C6: 出院记录 | D6: 000 | E6: CYJL | F6: BBYV | G6: 8 | L6: 1
A7: 手术麻醉记录 | B7: 6 | C7: 手术麻醉记录 | D7: 000 | E7: SSMZJL | F7: RSYSYV | G7: 5 | L7: 1
A8: 护理记录 | B8: 8 | C8: 护理记录 | D8: 000 | E8: HLJL | F8: RGYV | G8: 14 | L8: 1
A9: 体温单 | B9: 9 | C9: 体温单 | D9: 000 | E9: TWD | F9: WIU | G9: 13 | L9: 1
A10: 住院医嘱 | B10: 10 | C10: 住院医嘱 | D10: 000 | E10: YZD | F10: AKU | G10: 21 | L10: 1
A11: 产程图 | B11: 11 | C11: 产程图 | D11: 000 | E11: CCT | F11: UTL | G11: 16 | L11: 1
A12: 知情同意书 | B12: 12 | C12: 知情同意书 | D12: 000 | E12: ZQTYS | F12: TNMUN | G12: 7 | L12: 1
A13: 检验报告 | B13: 13 | C13: 检验报告 | D13: 000 | E13: JYBG | F13: SCRT | G13: 22 | L13: 1
... A25: 科室交班 | B25: 32 | C25: 科室交班 | D25: 000 | E25: KSJB | F25: TPUG | G25: 19 | L25: 1
A26: 操作记录 | B26: 33 | C26: 操作记录 | D26: 000 | E26: CZJL | G26: 6 | L26: 1
A27: 其他门诊病历 | B27: 34 | C27: 其他门诊病历 | D27: 000 | E27: QTMZBL | F27: UQYUD | G27: 32 | L27: 1
A28: 申请单 | B28: 35 | C28: 申请单 | D28: 000 | E28: SQD | F28: JYU | G28: 25 | L28: 1
A29: 医学量表 | B29: 36 | C29: 医学量表 | D29: 000 | E29: YXLB | F29: AIJG | G29: 11 | L29: 1
A30: 其他医生文书 | B30: 37 | C30: 其他医生文书 | D30: 000 | E30: QTYSWS | F30: AWATYN | G30: 10 | L30: 1
A31: 上报卡 | B31: 38 | C31: 上报卡 | D31: 000 | E31: SBK | F31: HRH | G31: 26 | L31: 1
A32: 家床病历 | B32: 39 | C32: 家床病历 | D32: 000 | E32: JCBL | F32: PYUD | G32: 35 | L32: 1
A33: 诊疗评估 | B33: 40 | C33: 诊疗评估 | D33: 000 | E33: ZLPG | F33: YUYW | G33: 36 | L33: 1
A34: 急诊抢救记录 | B34: 41 | C34: 急诊抢救记录 | D34: 000 | E34: JZQJJL | F34: QYRFYV | G34: 34 | L34: 1
A35: 质控评分记录 | B35: 42 | C35: 质控评分记录 | D35: 000 | E35: ZKPFJL | F35: RRYWYV | G35: 37 | L35: 1
A36: 图片病历 | B36: 43 | C36: 图片病历 | D36: 000 | E36: TPBL | F36: LTUD | G36: 38 | L36: 1
A37: 其他HIS类文书 | B37: 44 | C37: 其他HIS类文书 | D37: 000 | E37: QTHISLWS | F37: AWHISOYN | G37: 39 | L37: 1
A38: 治疗方案 | B38: 45 | C38: 治疗方案 | D38: 000 | E38: ZLFA | F38: IUYP | G38: 40 | L38: 1
... A67: 日常病程记录 | B67: 302 | C67: 日常病程记录 | D67: 3 | E67: RCBCJL | F67: JIUTYV | G67: 15 | L67: 1
A68: 主治查房记录 | B68: 303 | C68: 主治查房记录 | D68: 3 | E68: ZZCFJL | F68: YISYYV | G68: 16 | L68: 1
A69: 科主任或主任（副主任）医师查房记录 | B69: 304 | C69: 科主任或主任（副主任）医师查房记录 | D69: 3 | E69: KZRHZR FZR YSCFJL | F69: TYWAYWGYWAJSYYV | G69: 17 | L69: 1
A70: 疑难病例讨论 | B70: 305 | C70: 疑难病例讨论 | D70: 3 | E70: YNBLTLJL | F70: XCUWYYYV | G70: 18 | L70: 1
A71: 交接班记录 | B71: 306 | C71: 交接班记录 | D71: 3 | E71: JJBJL | F71: URGYV | G71: 19 | L71: 1
A72: 转科记录 | B72: 307 | C72: 转科记录 | D72: 3 | E72: ZKJL | F72: LTYV | G72: 20 | L72: 1
A73: 阶段小结 | B73: 308 | C73: 阶段小结 | D73: 3 | E73: JDXJ | F73: BWIX | G73: 21 | L73: 1
A74: 抢救记录 | B74: 309 | C74: 抢救记录 | D74: 3 | E74: QJJL | F74: RFYV | G74: 22 | L74: 1
A75: 传染病防控 | B75: 310 | C75: 传染病防控 | D75: 3 | E75: CRBFK | F75: WIUBR | G75: 149 | L75: 1
A76: 输血记录 | B76: 311 | C76: 输血记录 | D76: 3 | E76: SXJL | F76: LTYV | G76: 151 | L76: 1
A77: 死亡病例讨论记录 | B77: 312 | C77: 死亡病例讨论记录 | D77: 3 | E77: SWBLTLJL | F77: GYUWYYYV | G77: 152 | L77: 1
A78: 术后首次病程记录 | B78: 313 | C78: 术后首次病程记录 | D78: 3 | E78: SHSCBCJL | F78: SRUUUTYV | G78: 153 | L78: 1
A79: 术前小结 | B79: 314 | C79: 术前小结 | D79: 3 | E79: SQXJ | F79: SUIX | G79: 200 | L79: 1
...

Sheet AI平台数据元(排序备份)
A1: 01 | B1: 患者信息 | C1: =VLOOKUP(D1,#REF!,2,0) -> #REF! | D1: 患者基本信息 | E1: =VLOOKUP(C1,数据集标准分类!E:F,2,0) -> #REF! | F1: =VLOOKUP(D1,数据集标准分类!G:H,2,0) -> #N/A | G1: DE01.00.009.00 | H1: health_archives_no | I1: healthArchivesNo | J1: 健康档案编号 | K1: 城乡居民个人健康档案的编号 | L1: 1
A2: 01 | B2: 患者信息 | C2: =VLOOKUP(D2,#REF!,2,0) -> #REF! | D2: 患者基本信息 | E2: =VLOOKUP(C2,数据集标准分类!E:F,2,0) -> #REF! | F2: =VLOOKUP(D2,数据集标准分类!G:H,2,0) -> #N/A | G2: DE02.01.044.00 | H2: insur_class_code | I2: insurClassCode | J2: 医保类别代码 | K2: 患者本人参加的医疗保险类别在特定编码体系中的代码 | L2: 2
A3: 01 | B3: 患者信息 | C3: =VLOOKUP(D3,#REF!,2,0) -> #REF! | D3: 患者基本信息 | E3: =VLOOKUP(C3,数据集标准分类!E:F,2,0) -> #REF! | F3: =VLOOKUP(D3,数据集标准分类!G:H,2,0) -> #N/A | G3: DE02.01.005.00 | H3: birth_date | I3: birthDate | J3: 出生日期 | K3: 患者出生当日的公元纪年日期的完整描述 | L3: 3
A4: 01 | B4: 患者信息 | C4: =VLOOKUP(D4,#REF!,2,0) -> #REF! | D4: 患者基本信息 | E4: =VLOOKUP(C4,数据集标准分类!E:F,2,0) -> #REF! | F4: =VLOOKUP(D4,数据集标准分类!G:H,2,0) -> #N/A | G4: DE02.01.026.00 | H4: age | I4: age | J4: 年龄 | K4: 患者年龄满1周岁的实足年龄，为患者出生后按照日历计算的历法年龄，以实足年龄的相应整数填写 | L4: 4
A5: 01 | B5: 患者信息 | C5: =VLOOKUP(D5,#REF!,2,0) -> #REF! | D5: 患者基本信息 | E5: =VLOOKUP(C5,数据集标准分类!E:F,2,0) -> #REF! | F5: =VLOOKUP(D5,数据集标准分类!G:H,2,0) -> #N/A | G5: DE02.01.032.00 | H5: chronological_age | I5: chronologicalAge | J5: 实足年龄 | K5: 年龄不足1周岁的实足年龄的月龄，以分数形式表示：分数的整数部分代表实足月龄，分数部分分母为30，分子为不足1个月的天数 | L5: 5
A6: 01 | B6: 患者信息 | C6: =VLOOKUP(D6,#REF!,2,0) -> #REF! | D6: 患者基本信息 | E6: =VLOOKUP(C6,数据集标准分类!E:F,2,0) -> #REF! | F6: =VLOOKUP(D6,数据集标准分类!G:H,2,0) -> #N/A | G6: DE02.01.040.00 | H6: sex_code | I6: sexCode | J6: 性别代码 | K6: 患者生理性别在特定编码体系中的代码 | L6: 6
A7: 01 | B7: 患者信息 | C7: =VLOOKUP(D7,#REF!,2,0) -> #REF! | D7: 患者基本信息 | E7: =VLOOKUP(C7,数据集标准分类!E:F,2,0) -> #REF! | F7: =VLOOKUP(D7,数据集标准分类!G:H,2,0) -> #N/A | G7: DE01.00.004.00 | H7: case_no | I7: caseNo | J7: 病案号 | K7: 本医疗机构为患者住院病案设置的唯一性编码。原则上，同一患者在同一医疗机构多次住院应当使用同一病案号 | L7: 7
A8: 01 | B8: 患者信息 | C8: =VLOOKUP(D8,#REF!,2,0) -> #REF! | D8: 患者基本信息 | E8: =VLOOKUP(C8,数据集标准分类!E:F,2,0) -> #REF! | F8: =VLOOKUP(D8,数据集标准分类!G:H,2,0) -> #N/A | G8: DE02.01.018.00 | H8: marital_status_code | I8: maritalStatusCode | J8: 婚姻状况代码 | K8: 患者当前婚姻状况在特定编码体系中的代码 | L8: 8
A9: 01 | B9: 患者信息 | C9: =VLOOKUP(D9,#REF!,2,0) -> #REF! | D9: 患者基本信息 | E9: =VLOOKUP(C9,数据集标准分类!E:F,2,0) -> #REF! | F9: =VLOOKUP(D9,数据集标准分类!G:H,2,0) -> #N/A | G9: DE02.01.052.00 | H9: occup_class_code | I9: occupClassCode | J9: 职业分类代码 | K9: 患者当前从事的职业类别在特定编码体系中的代码 | L9: 9
A10: 01 | B10: 患者信息 | C10: =VLOOKUP(D10,#REF!,2,0) -> #REF! | D10: 患者基本信息 | E10: =VLOOKUP(C10,数据集标准分类!E:F,2,0) -> #REF! | F10: =VLOOKUP(D10,数据集标准分类!G:H,2,0) -> #N/A | G10: DE02.01.039.68 | H10: contacts_name | I10: contactsName | J10: 联系人姓名 | K10: 联系人在公安户籍管理部门正式登记注册的姓氏和名称 | L10: 10
A11: 01 | B11: 患者信息 | C11: =VLOOKUP(D11,#REF!,2,0) -> #REF! | D11: 患者基本信息 | E11: =VLOOKUP(C11,数据集标准分类!E:F,2,0) -> #REF! | F11: =VLOOKUP(D11,数据集标准分类!G:H,2,0) -> #N/A | G11: DE06.00.050.00 | H11: create_archives_date | I11: createArchivesDate | J11: 建档日期 | K11: 患者电子病历初次建档完成时的公元纪年日期和时间的完整描述 | L11: 11
A12: 01 | B12: 患者信息 | C12: =VLOOKUP(D12,#REF!,2,0) -> #REF! | D12: 患者基本信息 | E12: =VLOOKUP(C12,数据集标准分类!E:F,2,0) -> #REF! | F12: =VLOOKUP(D12,数据集标准分类!G:H,2,0) -> #N/A | G12: DE02.01.039.01 | H12: patient_name | I12: patientName | J12: 患者姓名 | K12: 首次为患者建立电子病历的人员在公安户籍管理部门正式登记注册的姓氏和名称 | L12: 12
... A739: 02 | B739: 电子病历 | C739: =VLOOKUP(D739,#REF!,2,0) -> #REF! | D739: 一般护理记录 | E739: =VLOOKUP(C739,数据集标准分类!E:F,2,0) -> #REF! | F739: =VLOOKUP(D739,数据集标准分类!G:H,2,0) -> #N/A | G739: DE06.00.209.00 | H739: nursing_oper_result | I739: nursingOperResult | J739: 护理操作结果 | K739: 多个护理操作结果的详细描述 | L739: 27
A740: 02 | B740: 电子病历 | C740: =VLOOKUP(D740,#REF!,2,0) -> #REF! | D740: 一般护理记录 | E740: =VLOOKUP(C740,数据集标准分类!E:F,2,0) -> #REF! | F740: =VLOOKUP(D740,数据集标准分类!G:H,2,0) -> #N/A | G740: ZOE99.00.02.296 | H740: send_op_safety_check_flag | I740: sendOpSafetyCheckFlag | J740: 发出手术安全核对表标志 | K740: 对接受手术治疗的患者，标识是否已发出手术安全核对表的标志 | L740: 28
A741: 02 | B741: 电子病历 | C741: =VLOOKUP(D741,#REF!,2,0) -> #REF! | D741: 一般护理记录 | E741: =VLOOKUP(C741,数据集标准分类!E:F,2,0) -> #REF! | F741: =VLOOKUP(D741,数据集标准分类!G:H,2,0) -> #N/A | G741: ZOE99.00.03.2013 | H741: take_back_op_safety_check_flag | I741: takeBackOpSafetyCheckFlag | J741: 收回手术安全核对表标志 | K741: 对接受手术治疗的患者，标识是否已收回手术安全核对表的标志 | L741: 29
A742: 02 | B742: 电子病历 | C742: =VLOOKUP(D742,#REF!,2,0) -> #REF! | D742: 一般护理记录 | E742: =VLOOKUP(C742,数据集标准分类!E:F,2,0) -> #REF! | F742: =VLOOKUP(D742,数据集标准分类!G:H,2,0) -> #N/A | G742: ZOE99.00.02.298 | H742: send_op_risk_assmnt_flag | I742: sendOpRiskAssmntFlag | J742: 发出手术风险评估表标志 | K742: 对接受手术治疗的患者，标识是否已发出手术风险评估表的标志 | L742: 30
A743: 02 | B743: 电子病历 | C743: =VLOOKUP(D743,#REF!,2,0) -> #REF! | D743: 一般护理记录 | E743: =VLOOKUP(C743,数据集标准分类!E:F,2,0) -> #REF! | F743: =VLOOKUP(D743,数据集标准分类!G:H,2,0) -> #N/A | G743: ZOE99.00.02.299 | H743: take_back_op_risk_assmnt_flag | I743: takeBackOpRiskAssmntFlag | J743: 收回手术风险评估表标志 | K743: 对接受手术治疗的患者，标识是否已收回手术风险评估表的标志 | L743: 31
A744: 02 | B744: 电子病历 | C744: =VLOOKUP(D744,#REF!,2,0) -> #REF! | D744: 一般护理记录 | E744: =VLOOKUP(C744,数据集标准分类!E:F,2,0) -> #REF! | F744: =VLOOKUP(D744,数据集标准分类!G:H,2,0) -> #N/A | G744: DE06.00.201.00 | H744: isolation_flag | I744: isolationFlag | J744: 隔离标志 | K744: 标识对患者是否采取隔离措施的标志 | L744: 32
A745: 02 | B745: 电子病历 | C745: =VLOOKUP(D745,#REF!,2,0) -> #REF! | D745: 一般护理记录 | E745: =VLOOKUP(C745,数据集标准分类!E:F,2,0) -> #REF! | F745: =VLOOKUP(D745,数据集标准分类!G:H,2,0) -> #N/A | G745: DE06.00.202.00 | H745: isolation_kind_code | I745: isolationKindCode | J745: 隔离种类代码 | K745: 对患者采取的隔离种类在特定编码体系中的代码 | L745: 33
A746: 02 | B746: 电子病历 | C746: =VLOOKUP(D746,#REF!,2,0) -> #REF! | D746: 出入量记录 | E746: =VLOOKUP(C746,数据集标准分类!E:F,2,0) -> #REF! | F746: =VLOOKUP(D746,数据集标准分类!G:H,2,0) -> #N/A | G746: DE04.10.188.00 | H746: weight | I746: weight | J746: 体重（kg） | K746: 患者体重的测量值，计量单位为kg | L746: 1
A747: 02 | B747: 电子病历 | C747: =VLOOKUP(D747,#REF!,2,0) -> #REF! | D747: 出入量记录 | E747: =VLOOKUP(C747,数据集标准分类!E:F,2,0) -> #REF! | F747: =VLOOKUP(D747,数据集标准分类!G:H,2,0) -> #N/A | G747: DE05.01.024.00 | H747: diag_wm_dis_code | I747: diagWmDisCode | J747: 诊断西医疾病代码（西医疾病诊断代码） | K747: 患者所患的疾病诊断特定编码体系中的编码 | L747: 2
A748: 02 | B748: 电子病历 | C748: =VLOOKUP(D748,#REF!,2,0) -> #REF! | D748: 出入量记录 | E748: =VLOOKUP(C748,数据集标准分类!E:F,2,0) -> #REF! | F748: =VLOOKUP(D748,数据集标准分类!G:H,2,0) -> #N/A | G748: DE06.00.211.00 | H748: nursing_grade_code | I748: nursingGradeCode | J748: 护理等级代码 | K748: 护理级别的分类在特定编码体系中的代码 | L748: 3
A749: 02 | B749: 电子病历 | C749: =VLOOKUP(D749,#REF!,2,0) -> #REF! | D749: 出入量记录 | E749: =VLOOKUP(C749,数据集标准分类!E:F,2,0) -> #REF! | F749: =VLOOKUP(D749,数据集标准分类!G:H,2,0) -> #N/A | G749: DE06.00.212.00 | H749: nursing_type_code | I749: nursingTypeCode | J749: 护理类型代码 | K749: 护理类型的分类在特定编码体系中的代码 | L749: 4
A750: 02 | B750: 电子病历 | C750: =VLOOKUP(D750,#REF!,2,0) -> #REF! | D750: 出入量记录 | E750: =VLOOKUP(C750,数据集标准分类!E:F,2,0) -> #REF! | F750: =VLOOKUP(D750,数据集标准分类!G:H,2,0) -> #N/A | G750: DE02.10.031.00 | H750: observe_item_name | I750: observeItemName | J750: 观察项目名称 | K750: 护理观察项目的名称，如患者神志状态、饮食情况，皮肤情况、氧疗情况、排尿排便情况，流量、出量、入量等等，根据护理内容的不同选择不同的观察项目名称 | L750: 5
A751: 02 | B751: 电子病历 | C751: =VLOOKUP(D751,#REF!,2,0) -> #REF! | D751: 出入量记录 | E751: =VLOOKUP(C751,数据集标准分类!E:F,2,0) -> #REF! | F751: =VLOOKUP(D751,数据集标准分类!G:H,2,0) -> #N/A | G751: DE02.10.028.00 | H751: observe_result | I751: observeResult | J751: 观察结果 | K751: 对护理观察项目结果的详细描述 | L751: 6
A752: 02 | B752: 电子病历 | C752: =VLOOKUP(D752,#REF!,2,0) -> #REF! | D752: 出入量记录 | E752: =VLOOKUP(C752,数据集标准分类!E:F,2,0) -> #REF! | F752: =VLOOKUP(D752,数据集标准分类!G:H,2,0) -> #N/A | G752: DE06.00.342.00 | H752: nursing_oper_name | I752: nursingOperName | J752: 护理操作名称 | K752: 多个护理操作项目的名称 | L752: 7
A753: 02 | B753: 电子病历 | C753: =VLOOKUP(D753,#REF!,2,0) -> #REF! | D753: 出入量记录 | E753: =VLOOKUP(C753,数据集标准分类!E:F,2,0) -> #REF! | F753: =VLOOKUP(D753,数据集标准分类!G:H,2,0) -> #N/A | G753: DE06.00.210.00 | H753: nursing_oper_item_name | I753: nursingOperItemName | J753: 护理操作项目类目名称 | K753: 进行护理操作的具体名称 | L753: 8
A754: 02 | B754: 电子病历 | C754: =VLOOKUP(D754,#REF!,2,0) -> #REF! | D754: 出入量记录 | E754: =VLOOKUP(C754,数据集标准分类!E:F,2,0) -> #REF! | F754: =VLOOKUP(D754,数据集标准分类!G:H,2,0) -> #N/A | G754: DE06.00.209.00 | H754: nursing_oper_result | I754: nursingOperResult | J754: 护理操作结果 | K754: 多个护理操作结果的详细描述 | L754: 9
A755: 02 | B755: 电子病历 | C755: =VLOOKUP(D755,#REF!,2,0) -> #REF! | D755: 出入量记录 | E755: =VLOOKUP(C755,数据集标准分类!E:F,2,0) -> #REF! | F755: =VLOOKUP(D755,数据集标准分类!G:H,2,0) -> #N/A | G755: DE06.00.136.00 | H755: drug_usage | I755: drugUsage | J755: 药品用法 | K755: 药物（含中药）治疗疾病具体用法的描述 | L755: 10
A756: 02 | B756: 电子病历 | C756: =VLOOKUP(D756,#REF!,2,0) -> #REF! | D756: 出入量记录 | E756: =VLOOKUP(C756,数据集标准分类!E:F,2,0) -> #REF! | F756: =VLOOKUP(D756,数据集标准分类!G:H,2,0) -> #N/A | G756: DE06.00.164.00 | H756: chm_use_class_code | I756: chmUseClassCode | J756: 中药使用类别代码 | K756: 临床治疗中中药使用情况分类在特定编码体系中的代码 | L756: 11
A757: 02 | B757: 电子病历 | C757: =VLOOKUP(D757,#REF!,2,0) -> #REF! | D757: 出入量记录 | E757: =VLOOKUP(C757,数据集标准分类!E:F,2,0) -> #REF! | F757: =VLOOKUP(D757,数据集标准分类!G:H,2,0) -> #N/A | G757: DE06.00.133.00 | H757: drug_use_freq_code | I757: drugUseFreqCode | J757: 药品使用频次代码 | K757: 标识单位时间内药物使用的次数 | L757: 12
... A766: 02 | B766: 电子病历 | C766: =VLOOKUP(D766,#REF!,2,0) -> #REF! | D766: 手术护理记录 | E766: =VLOOKUP(C766,数据集标准分类!E:F,2,0) -> #REF! | F766: =VLOOKUP(D766,数据集标准分类!G:H,2,0) -> #N/A | G766: DE04.50.001.00 | H766: abo_blood_group_code | I766: aboBloodGroupCode | J766: ABO血型代码 | K766: 在本次住院期间进行血型检查明确，或既往病历资料能够明确的患者ABO血型类别在特定编码体系中的代码 | L766: 2
A767: 02 | B767: 电子病历 | C767: =VLOOKUP(D767,#REF!,2,0) -> #REF! | D767: 手术护理记录 | E767: =VLOOKUP(C767,数据集标准分类!E:F,2,0) -> #REF! | F767: =VLOOKUP(D767,数据集标准分类!G:H,2,0) -> #N/A | G767: DE04.50.010.00 | H767: rh_blood_group_code | I767: rhBloodGroupCode | J767: Rh血型代码 | L767: 3
A768: 02 | B768: 电子病历 | C768: =VLOOKUP(D768,#REF!,2,0) -> #REF! | D768: 手术护理记录 | E768: =VLOOKUP(C768,数据集标准分类!E:F,2,0) -> #REF! | F768: =VLOOKUP(D768,数据集标准分类!G:H,2,0) -> #N/A | G768: DE05.01.024.00 | H768: diag_wm_dis_code | I768: diagWmDisCode | J768: 诊断西医疾病代码（西医疾病诊断代码） | L768: 4
A769: 02 | B769: 电子病历 | C769: =VLOOKUP(D769,#REF!,2,0) -> #REF! | D769: 手术护理记录 | E769: =VLOOKUP(C769,数据集标准分类!E:F,2,0) -> #REF! | F769: =VLOOKUP(D769,数据集标准分类!G:H,2,0) -> #N/A | G769: DE05.01.024.17 | H769: preop_diag_wm_dis_code | I769: preopDiagWmDisCode | J769: 术前诊断西医疾病代码 | K769: 在本次住院期间进行血型检查明确，或既往病历资料能够明确的患者Rh血型的类别代码 | L769: 5
A770: 02 | B770: 电子病历 | C770: =VLOOKUP(D770,#REF!,2,0) -> #REF! | D770: 手术护理记录 | E770: =VLOOKUP(C770,数据集标准分类!E:F,2,0) -> #REF! | F770: =VLOOKUP(D770,数据集标准分类!G:H,2,0) -> #N/A | G770: DE06.00.093.00 | H770: op_oper_code | I770: opOperCode | J770: 手术/操作代码 | K770: 术前诊断在特定编码体系中的编码 | L770: 6
A771: 02 | B771: 电子病历 | C771: =VLOOKUP(D771,#REF!,2,0) -> #REF! | D771: 手术护理记录 | E771: =VLOOKUP(C771,数据集标准分类!E:F,2,0) -> #REF! | F771: =VLOOKUP(D771,数据集标准分类!G:H,2,0) -> #N/A | G771: DE02.01.039.00 | H771: full_name | I771: fullName | J771: 姓名 | K771: 为患者实施手术的主要执行人员的在公安户籍管理部门正式登记注册的姓氏和名称 | L771: 7
A772: 02 | B772: 电子病历 | C772: =VLOOKUP(D772,#REF!,2,0) -> #REF! | D772: 手术护理记录 | E772: =VLOOKUP(C772,数据集标准分类!E:F,2,0) -> #REF! | F772: =VLOOKUP(D772,数据集标准分类!G:H,2,0) -> #N/A | G772: DE06.00.187.00 | H772: op_oper_target_papt_name | I772: opOperTargetPaptName | J772: 手术/操作目标部位名称 | K772: 实施手术的人体部位名称 | L772: 8
A773: 02 | B773: 电子病历 | C773: =VLOOKUP(D773,#REF!,2,0) -> #REF! | D773: 手术护理记录 | E773: =VLOOKUP(C773,数据集标准分类!E:F,2,0) -> #REF! | F773: =VLOOKUP(D773,数据集标准分类!G:H,2,0) -> #N/A | G773: ZOE99.00.03.4706 | H773: op_end_time | I773: opEndTime | J773: 手术结束时间 | K773: 对患者结束手术操作时的公元纪年日期和时间的完整描述 | L773: 9
A774: 02 | B774: 电子病历 | C774: =VLOOKUP(D774,#REF!,2,0) -> #REF! | D774: 手术护理记录 | E774: =VLOOKUP(C774,数据集标准分类!E:F,2,0) -> #REF! | F774: =VLOOKUP(D774,数据集标准分类!G:H,2,0) -> #N/A | G774: ZOE99.00.03.1826 | H774: op_start_time | I774: opStartTime | J774: 手术开始时间 | K774: 对患者开始手术操作时的公元纪年日期和时间的完整描述 | L774: 10
...

Sheet 数据元信息
A2: 数据集一级分类 | B2: 一级分类ID | C2: 数据集二级分类 | D2: 二级分类ID | F2: 数据集排序 | G2: 数据元标准编码 | H2: 数据元英文名 | I2: 数据元名称 | J2: 数据元新英文名 | K2: 数据元新名称 | L2: 数据元定义 | M2: 英文名是否变更 | N2: 中文名是否变更 | O2: 数据元排序 | P2: EMR4数据元编码 | Q2: 新增时间 | R2: 操作人 | S2: 是否隐私信息 | T2: 备注 | U2: onelink旧架构找不到字段 | V2: onelink新架构找不到字段 | W2: 数据处理排序号
A3: 电子病历 | B3: 02 | C3: 门(急)诊病历 | D3: =VLOOKUP(C3,#REF!,2,0) -> #REF! | E3: =VLOOKUP(D3,数据集标准分类!E:F,2,0) -> #REF! | F3: 1 | G3: DE02.10.023.00 | H3: is_allergy_history_flag | I3: 是否过敏史标志 | J3: allergy_hist_flag | K3: 过敏史标志 | L3: 标识患者有无过敏经历的标志 | M3: 是 | N3: 是 | O3: 1 | P3: =VLOOKUP(I3,#REF!,2,0) -> #REF! | W3: 1
A4: 电子病历 | B4: 02 | C4: 门(急)诊病历 | D4: =VLOOKUP(C4,#REF!,2,0) -> #REF! | E4: =VLOOKUP(D4,数据集标准分类!E:F,2,0) -> #REF! | F4: 1 | G4: DE02.10.022.00 | H4: allergy_history_desc | I4: 过敏史描述 | J4: allergy_hist_desc | K4: 过敏史描述 | L4: 患者既往发生过敏情况的详细描述 | M4: 是 | N4: 否 | O4: 2 | P4: =VLOOKUP(I4,#REF!,2,0) -> #REF! | W4: 2
A5: 电子病历 | B5: 02 | C5: 门(急)诊病历 | D5: =VLOOKUP(C5,#REF!,2,0) -> #REF! | E5: =VLOOKUP(D5,数据集标准分类!E:F,2,0) -> #REF! | F5: 1 | G5: DE06.00.062.00 | H5: visit_time | I5: 就诊日期时间 | J5: visit_time | K5: 就诊时间 | L5: 患者在门（急）诊就诊结束时的公元纪年日期和时间的完整描述 | M5: 否 | N5: 是 | O5: 3 | P5: =VLOOKUP(I5,#REF!,2,0) -> #REF! | W5: 3
A6: 电子病历 | B6: 02 | C6: 门(急)诊病历 | D6: =VLOOKUP(C6,#REF!,2,0) -> #REF! | E6: =VLOOKUP(D6,数据集标准分类!E:F,2,0) -> #REF! | F6: 1 | G6: DE06.00.196.00 | H6: first_visit_flag_code | I6: 初诊标志代码 | J6: first_visit_flag_code | K6: 首诊标志代码 | L6: 患者是否因该疾病首次就诊的分类代码 | M6: 否 | N6: 是 | O6: 4 | P6: =VLOOKUP(I6,#REF!,2,0) -> #REF! | W6: 4
A7: 电子病历 | B7: 02 | C7: 门(急)诊病历 | D7: =VLOOKUP(C7,#REF!,2,0) -> #REF! | E7: =VLOOKUP(D7,数据集标准分类!E:F,2,0) -> #REF! | F7: 1 | G7: DE04.01.119.00 | H7: chief_complaint | I7: 主诉 | J7: chief_complaint | K7: 主诉 | L7: 对患者本次疾病相关的主要症状及其持续时间的描述，一般由患者本人或监护人描述 | M7: 否 | N7: 否 | O7: 5 | P7: =VLOOKUP(I7,#REF!,2,0) -> #REF! | W7: 5
A8: 电子病历 | B8: 02 | C8: 门(急)诊病历 | D8: =VLOOKUP(C8,#REF!,2,0) -> #REF! | E8: =VLOOKUP(D8,数据集标准分类!E:F,2,0) -> #REF! | F8: 1 | G8: DE02.10.071.00 | H8: present_disease | I8: 现病史 | J8: pres_hist | K8: 现病史 | L8: 对患者当前所患疾病情况的详细描述 | M8: 是 | N8: 否 | O8: 6 | P8: =VLOOKUP(I8,#REF!,2,0) -> #REF! | W8: 6
A9: 电子病历 | B9: 02 | C9: 门(急)诊病历 | D9: =VLOOKUP(C9,#REF!,2,0) -> #REF! | E9: =VLOOKUP(D9,数据集标准分类!E:F,2,0) -> #REF! | F9: 1 | G9: DE02.10.099.00 | H9: past_history | I9: 既往史 | J9: past_hist | K9: 既往史 | L9: 既往健康状况及重要相关病史的描述 | M9: 是 | N9: 否 | O9: 7 | P9: =VLOOKUP(I9,#REF!,2,0) -> #REF! | W9: 7
A10: 电子病历 | B10: 02 | C10: 门(急)诊病历 | D10: =VLOOKUP(C10,#REF!,2,0) -> #REF! | E10: =VLOOKUP(D10,数据集标准分类!E:F,2,0) -> #REF! | F10: 1 | G10: ZOE99.00.00.00.520 | H10: epidemiological_history | I10: 流行病学史 | J10: epidemiology_hist | K10: 流行病学史 | L10: 患者流行病学史描述 | M10: 是 | N10: 否 | O10: 8 | P10: =VLOOKUP(I10,#REF!,2,0) -> #REF! | W10: 8
A11: 电子病历 | B11: 02 | C11: 门(急)诊病历 | D11: =VLOOKUP(C11,#REF!,2,0) -> #REF! | E11: =VLOOKUP(D11,数据集标准分类!E:F,2,0) -> #REF! | F11: 1 | G11: DE04.10.258.00 | H11: physical_exam | I11: 辅助检查项目名称 | J11: physique_exam | K11: 体格检查 | L11: 由门急诊接诊医师对患者进行的体格检查项目及主要检查结果的描述,包括主要的阳性体征和必要的阴性体征 | M11: 是 | N11: 是 | O11: 9 | P11: =VLOOKUP(I11,#REF!,2,0) -> #REF! | W11: 9
A12: 电子病历 | B12: 02 | C12: 门(急)诊病历 | D12: =VLOOKUP(C12,#REF!,2,0) -> #REF! | E12: =VLOOKUP(D12,数据集标准分类!E:F,2,0) -> #REF! | F12: 1 | G12: DE02.10.028.00 | H12: observe_result | I12: 观察结果 | J12: observe_result | K12: 观察结果 | L12: 中医“四诊”观察结果的详细描述，包括望、闻、问、切四诊内容 | M12: 否 | N12: 否 | O12: 10 | P12: =VLOOKUP(I12,#REF!,2,0) -> #REF! | W12: 10
A13: 电子病历 | B13: 02 | C13: 门(急)诊病历 | D13: =VLOOKUP(C13,#REF!,2,0) -> #REF! | E13: =VLOOKUP(D13,数据集标准分类!E:F,2,0) -> #REF! | F13: 1 | G13: DE04.30.010.00 | H13: auxiliary_exam_item_name | I13: 辅助检查项目 | J13: auxiliary_exam_item_name | K13: 辅助检查项目名称 | L13: 患者辅助检查、检验项目的通用名称 | M13: 否 | N13: 是 | O13: 11 | P13: =VLOOKUP(I13,#REF!,2,0) -> #REF! | W13: 11
A14: 电子病历 | B14: 02 | C14: 门(急)诊病历 | D14: =VLOOKUP(C14,#REF!,2,0) -> #REF! | E14: =VLOOKUP(D14,数据集标准分类!E:F,2,0) -> #REF! | F14: 1 | G14: DE04.30.009.00 | H14: auxiliary_exam_result | I14: 辅助检查结果 | J14: auxiliary_exam_result | K14: 辅助检查结果 | L14: 患者辅助检查、检验结果的详细描述 | M14: 否 | N14: 否 | O14: 12 | P14: =VLOOKUP(I14,#REF!,2,0) -> #REF! | W14: 12
... A62: 电子病历 | B62: 02 | C62: 急诊留观病历 | D62: =VLOOKUP(C62,#REF!,2,0) -> #REF! | E62: =VLOOKUP(D62,数据集标准分类!E:F,2,0) -> #REF! | F62: 2 | G62: DE06.00.093.00 | H62: operation_code | I62: 手术／操作代码 | J62: op_oper_code | K62: 手术/操作代码 | L62: 患者住院期间实施的手术及操作在特定编码体系中的编码 | M62: 是 | N62: 是 | O62: 32 | P62: =VLOOKUP(I62,#REF!,2,0) -> #REF! | W62: 60
A63: 电子病历 | B63: 02 | C63: 急诊留观病历 | D63: =VLOOKUP(C63,#REF!,2,0) -> #REF! | E63: =VLOOKUP(D63,数据集标准分类!E:F,2,0) -> #REF! | F63: 2 | G63: DE06.00.187.00 | H63: opn_target_papt_name | I63: 手术/操作目标部位名称 | J63: op_oper_target_papt_name | K63: 手术/操作目标部位名称 | L63: 实施手术/操作的人体部位名称 | M63: 是 | N63: 否 | O63: 33 | P63: =VLOOKUP(I63,#REF!,2,0) -> #REF! | V63: 是 | W63: 61
A64: 电子病历 | B64: 02 | C64: 急诊留观病历 | D64: =VLOOKUP(C64,#REF!,2,0) -> #REF! | E64: =VLOOKUP(D64,数据集标准分类!E:F,2,0) -> #REF! | F64: 2 | G64: DE08.50.037.00 | H64: intervention_material_name | I64: 介入物名称 | J64: inven_matl_name | K64: 介入物名称 | L64: 实施手术操作时使用/放置的材料/药物的名称 | M64: 是 | N64: 否 | O64: 34 | P64: =VLOOKUP(I64,#REF!,2,0) -> #REF! | V64: 是 | W64: 62
A65: 电子病历 | B65: 02 | C65: 急诊留观病历 | D65: =VLOOKUP(C65,#REF!,2,0) -> #REF! | E65: =VLOOKUP(D65,数据集标准分类!E:F,2,0) -> #REF! | F65: 2 | G65: DE06.00.251.00 | H65: operation_method | I65: 手术/操作方法 | J65: op_oper_method | K65: 手术/操作方法 | L65: 手术/操作方法的详细描述 | M65: 是 | N65: 否 | O65: 35 | P65: =VLOOKUP(I65,#REF!,2,0) -> #REF! | V65: 是 | W65: 63
A66: 电子病历 | B66: 02 | C66: 急诊留观病历 | D66: =VLOOKUP(C66,#REF!,2,0) -> #REF! | E66: =VLOOKUP(D66,数据集标准分类!E:F,2,0) -> #REF! | F66: 2 | G66: DE06.00.250.00 | H66: operation_times | I66: 手术/操作次数 | J66: op_oper_times | K66: 手术/操作次数 | L66: 实施手术/操作的次数 | M66: 是 | N66: 否 | O66: 36 | P66: =VLOOKUP(I66,#REF!,2,0) -> #REF! | W66: 64
A67: 电子病历 | B67: 02 | C67: 急诊留观病历 | D67: =VLOOKUP(C67,#REF!,2,0) -> #REF! | E67: =VLOOKUP(D67,数据集标准分类!E:F,2,0) -> #REF! | F67: 2 | G67: DE09.00.053.00 | H67: filling_record_time | I67: 填报日期时间 | J67: fill_out_time | K67: 填报时间 | L67: 完成此项业务活动时的公元纪年日期和时间的完整描述 | M67: 是 | N67: 是 | O67: 37 | P67: =VLOOKUP(I67,#REF!,2,0) -> #REF! | W67: 65
A68: 电子病历 | B68: 02 | C68: 急诊留观病历 | D68: =VLOOKUP(C68,#REF!,2,0) -> #REF! | E68: =VLOOKUP(D68,数据集标准分类!E:F,2,0) -> #REF! | F68: 2 | G68: DE09.00.119.00 | H68: attention_desc | I68: 注意事项 | J68: precautions_desc | K68: 注意事项 | L68: 对可能出现问题及采取相应措施的描述 | M68: 是 | N68: 否 | O68: 38 | P68: =VLOOKUP(I68,#REF!,2,0) -> #REF! | W68: 66
A69: 电子病历 | B69: 02 | C69: 急诊留观病历 | D69: =VLOOKUP(C69,#REF!,2,0) -> #REF! | E69: =VLOOKUP(D69,数据集标准分类!E:F,2,0) -> #REF! | F69: 2 | G69: DE06.00.185.00 | H69: patient_destination | I69: 患者去向 | J69: patient_destination | K69: 患者去向 | L69: 患者当前诊疗过程结束后的去向在特定编码体系中的代码，这里指离开急诊观察室或监护室后的去向 | M69: 否 | N69: 否 | O69: 39 | P69: =VLOOKUP(I69,#REF!,2,0) -> #REF! | W69: 67
A70: 电子病历 | B70: 02 | C70: 治疗记录 | D70: =VLOOKUP(C70,#REF!,2,0) -> #REF! | E70: =VLOOKUP(D70,数据集标准分类!E:F,2,0) -> #REF! | F70: 7 | G70: DE04.10.188.00 | H70: weight | I70: 体重（kg） | J70: weight | K70: 体重（kg） | L70: 患者体重的测量值，计量单位为kg | M70: 否 | N70: 否 | O70: 1 | P70: =VLOOKUP(I70,#REF!,2,0) -> #REF! | W70: 68
A71: 电子病历 | B71: 02 | C71: 治疗记录 | D71: =VLOOKUP(C71,#REF!,2,0) -> #REF! | E71: =VLOOKUP(D71,数据集标准分类!E:F,2,0) -> #REF! | F71: 7 | G71: DE05.01.024.00 | H71: west_med_diag_code | I71: 西医疾病诊断代码 | J71: diag_wm_dis_code | K71: 诊断西医疾病代码（西医疾病诊断代码） | L71: 患者所患的疾病诊断特定编码体系中的编码 | M71: 是 | N71: 是 | O71: 2 | P71: =VLOOKUP(I71,#REF!,2,0) -> #REF! | W71: 69
A72: 电子病历 | B72: 02 | C72: 治疗记录 | D72: =VLOOKUP(C72,#REF!,2,0) -> #REF! | E72: =VLOOKUP(D72,数据集标准分类!E:F,2,0) -> #REF! | F72: 7 | G72: DE06.00.018.00 | H72: deal_guidance_opinion | I72: 处理及指导意见 | J72: deal_guidance_opinion | K72: 处理及指导意见 | L72: 对某事件进行处理及指导意见内容的详细描述 | M72: 否 | N72: 否 | O72: 3 | P72: =VLOOKUP(I72,#REF!,2,0) -> #REF! | W72: 70
A73: 电子病历 | B73: 02 | C73: 治疗记录 | D73: =VLOOKUP(C73,#REF!,2,0) -> #REF! | E73: =VLOOKUP(D73,数据集标准分类!E:F,2,0) -> #REF! | F73: 7 | G73: DE06.00.507.00 | H73: is_clinic_operate_flag | I73: 是否有创诊疗操作标志 | J73: invasive_diag_treat_oper_flag | K73: 有创诊疗操作标志 | L73: 标识患者是否接受过有创诊疗操作的标志 | M73: 是 | N73: 是 | O73: 4 | P73: =VLOOKUP(I73,#REF!,2,0) -> #REF! | W73: 71
A74: 电子病历 | B74: 02 | C74: 治疗记录 | D74: =VLOOKUP(C74,#REF!,2,0) -> #REF! | E74: =VLOOKUP(D74,数据集标准分类!E:F,2,0) -> #REF! | F74: 7 | G74: DE06.00.093.00 | H74: operation_code | I74: 手术／操作代码 | J74: op_oper_code | K74: 手术/操作代码 | L74: 为患者实施的手术及操作在特定编码体系中的编码 | M74: 是 | N74: 是 | O74: 5 | P74: =VLOOKUP(I74,#REF!,2,0) -> #REF! | W74: 72
A75: 电子病历 | B75: 02 | C75: 治疗记录 | D75: =VLOOKUP(C75,#REF!,2,0) -> #REF! | E75: =VLOOKUP(D75,数据集标准分类!E:F,2,0) -> #REF! | F75: 7 | G75: DE06.00.094.00 | H75: operation_name | I75: 手术／操作名称 | J75: op_oper_name | K75: 手术/操作名称 | L75: 按照ICD-9-CM-3的名称 | M75: 是 | N75: 是 | O75: 6 | P75: =VLOOKUP(I75,#REF!,2,0) -> #REF! | W75: 73
A76: 电子病历 | B76: 02 | C76: 治疗记录 | D76: =VLOOKUP(C76,#REF!,2,0) -> #REF! | E76: =VLOOKUP(D76,数据集标准分类!E:F,2,0) -> #REF! | F76: 7 | G76: DE06.00.187.00 | H76: opn_target_papt_name | I76: 手术/操作目标部位名称 | J76: op_oper_target_papt_name | K76: 手术/操作目标部位名称 | L76: 实施操作的人体部位名称 | M76: 是 | N76: 否 | O76: 7 | P76: =VLOOKUP(I76,#REF!,2,0) -> #REF! | W76: 74
A77: 电子病历 | B77: 02 | C77: 治疗记录 | D77: =VLOOKUP(C77,#REF!,2,0) -> #REF! | E77: =VLOOKUP(D77,数据集标准分类!E:F,2,0) -> #REF! | F77: 7 | G77: DE08.50.037.00 | H77: intervention_material_name | I77: 介入物名称 | J77: inven_matl_name | K77: 介入物名称 | L77: 实施手术操作时使用/放置的材料/药物的名称 | M77: 是 | N77: 否 | O77: 8 | P77: =VLOOKUP(I77,#REF!,2,0) -> #REF! | W77: 75
... A119: 电子病历 | B119: 02 | C119: 一般手术记录 | D119: =VLOOKUP(C119,#REF!,2,0) -> #REF! | E119: =VLOOKUP(D119,数据集标准分类!E:F,2,0) -> #REF! | F119: 8 | G119: DE06.00.264.00 | H119: is_blood_trans_reaction_flag | I119: 是否输血反应标志 | J119: blood_transf_rxn_flag | K119: 输血反应标志 | L119: 标识患者术中输血后是否发生了输血反应的标志 | M119: 是 | N119: 是 | O119: 24 | P119: =VLOOKUP(I119,#REF!,2,0) -> #REF! | W119: 117
A120: 电子病历 | B120: 02 | C120: 一般手术记录 | D120: =VLOOKUP(C120,#REF!,2,0) -> #REF! | E120: =VLOOKUP(D120,数据集标准分类!E:F,2,0) -> #REF! | F120: 8 | G120: DE02.01.039.00 | H120: name | I120: 姓名 | J120: full_name | K120: 姓名 | L120: 为患者实施手术的主要执行人员在公安户籍管理部门正式登记注册的姓氏和名称 | M120: 是 | N120: 否 | O120: 25 | P120: =VLOOKUP(I120,#REF!,2,0) -> #REF! | S120: 是 | W120: 118
A121: 电子病历 | B121: 02 | C121: 一般手术记录 | D121: =VLOOKUP(C121,#REF!,2,0) -> #REF! | E121: =VLOOKUP(D121,数据集标准分类!E:F,2,0) -> #REF! | F121: 8 | G121: DE02.01.039.79 | H121: assistant1_name | I121: Ⅰ助姓名 | J121: assistant_1_name | K121: 一助姓名 | L121: 协助手术者完成手术及操作的第1助手在公安户籍管理部门正式登记注册的姓氏和名称 | M121: 是 | N121: 是 | O121: 26 | P121: =VLOOKUP(I121,#REF!,2,0) -> #REF! | S121: 是 | W121: 119
A122: 电子病历 | B122: 02 | C122: 一般手术记录 | D122: =VLOOKUP(C122,#REF!,2,0) -> #REF! | E122: =VLOOKUP(D122,数据集标准分类!E:F,2,0) -> #REF! | F122: 8 | G122: DE02.01.039.80 | H122: assistant2_name | I122: Ⅱ助姓名 | J122: assistant_2_name | K122: 二助姓名 | L122: 协助手术者完成手术及操作的第2助手在公安户籍管理部门正式登记注册的姓氏和名称 | M122: 是 | N122: 是 | O122: 27 | P122: =VLOOKUP(I122,#REF!,2,0) -> #REF! | S122: 是 | W122: 120
A123: 电子病历 | B123: 02 | C123: 一般手术记录 | D123: =VLOOKUP(C123,#REF!,2,0) -> #REF! | E123: =VLOOKUP(D123,数据集标准分类!E:F,2,0) -> #REF! | F123: 8 | G123: DE06.00.073.00 | H123: anesthesia_method_code | I123: 麻醉方式代码 | J123: anes_mode_code | K123: 麻醉方式代码 | L123: 为患者进行手术、操作时使用的麻醉方法在特定编码体系中的代码 | M123: 是 | N123: 否 | O123: 28 | P123: =VLOOKUP(I123,#REF!,2,0) -> #REF! | W123: 121
A124: 电子病历 | B124: 02 | C124: 麻醉术前访视 | D124: =VLOOKUP(C124,#REF!,2,0) -> #REF! | E124: =VLOOKUP(D124,数据集标准分类!E:F,2,0) -> #REF! | F124: 9 | G124: DE04.10.188.00 | H124: weight | I124: 体重（kg） | J124: weight | K124: 体重（kg） | L124: 患者体重的测量值，计量单位为kg | M124: 否 | N124: 否 | O124: 1 | P124: =VLOOKUP(I124,#REF!,2,0) -> #REF! | W124: 122
A125: 电子病历 | B125: 02 | C125: 麻醉术前访视 | D125: =VLOOKUP(C125,#REF!,2,0) -> #REF! | E125: =VLOOKUP(D125,数据集标准分类!E:F,2,0) -> #REF! | F125: 9 | G125: DE04.50.001.00 | H125: abo_blood_code | I125: ABO血型代码 | J125: abo_blood_group_code | K125: ABO血型代码 | L125: 在本次住院期间进行血型检查明确，或既往病历资料能够明确的患者ABO血型类别在特定编码体系中的代码 | M125: 是 | N125: 否 | O125: 2 | P125: =VLOOKUP(I125,#REF!,2,0) -> #REF! | W125: 123
A126: 电子病历 | B126: 02 | C126: 麻醉术前访视 | D126: =VLOOKUP(C126,#REF!,2,0) -> #REF! | E126: =VLOOKUP(D126,数据集标准分类!E:F,2,0) -> #REF! | F126: 9 | G126: DE04.50.010.00 | H126: rh_blood_code | I126: Rh血型代码 | J126: rh_blood_group_code | K126: Rh血型代码 | L126: 在本次住院期间进行血型检查明确，或既往病历资料能够明确的患者Rh血型的类别代码 | M126: 是 | N126: 否 | O126: 3 | P126: =VLOOKUP(I126,#REF!,2,0) -> #REF! | W126: 124
A127: 电子病历 | B127: 02 | C127: 麻醉术前访视 | D127: =VLOOKUP(C127,#REF!,2,0) -> #REF! | E127: =VLOOKUP(D127,数据集标准分类!E:F,2,0) -> #REF! | F127: 9 | G127: DE05.01.024.00 | H127: west_med_diag_code | I127: 西医疾病诊断代码 | J127: diag_wm_dis_code | K127: 诊断西医疾病代码（西医疾病诊断代码） | L127: 术前诊断在特定编码体系中的编码 | M127: 是 | N127: 是 | O127: 4 | P127: =VLOOKUP(I127,#REF!,2,0) -> #REF! | W127: 125
A128: 电子病历 | B128: 02 | C128: 麻醉术前访视 | D128: =VLOOKUP(C128,#REF!,2,0) -> #REF! | E128: =VLOOKUP(D128,数据集标准分类!E:F,2,0) -> #REF! | F128: 9 | G128: DE06.00.093.00 | H128: operation_code | I128: 手术／操作代码 | J128: op_oper_code | K128: 手术/操作代码 | L128: 拟为患者实施的手术及操作在特定编码体系中的编码 | M128: 是 | N128: 是 | O128: 5 | P128: =VLOOKUP(I128,#REF!,2,0) -> #REF! | W128: 126
A129: 电子病历 | B129: 02 | C129: 麻醉术前访视 | D129: =VLOOKUP(C129,#REF!,2,0) -> #REF! | E129: =VLOOKUP(D129,数据集标准分类!E:F,2,0) -> #REF! | F129: 9 | G129: DE06.00.073.00 | H129: anesthesia_method_code | I129: 麻醉方式代码 | J129: anes_mode_code | K129: 麻醉方式代码 | L129: 为患者进行手术、操作时拟使用的麻醉方法在特定编码体系中的代码 | M129: 是 | N129: 否 | O129: 6 | P129: =VLOOKUP(I129,#REF!,2,0) -> #REF! | W129: 127
...
